Workbook

Sheet Ratios
A1: RATIO ANALYSIS SPREADSHEET (in thousands, except share and per share data)
A2: 2025 | I2: 2024
A3: LIQUIDITY AND SOLVENCY RATIOS | F3: ENTER DATA IN YELLOW CELLS | I3: LIQUIDITY AND SOLVENCY RATIOS
A4: Current | I4: Current | N4: ENTER DATA IN YELLOW CELLS
B5: Current Assets | D5: =G5 -> 2586439000 | E5: =D5/D6 -> 15.503905 | F5: Current Assets: | G5: 2586439000 | J5: Current Assets | L5: =O5 -> 378802000 | M5: =L5/L6 -> 10.497492 | N5: Current Assets: | O5: 378802000
B6: Current Liabilities | D6: =G6 -> 166825000 | F6: Current Liabilities: | G6: 166825000 | J6: Current Liabilities | L6: =O6 -> 36085000 | N6: Current Liabilities: | O6: 36085000
A8: Quick | I8: Quick
B9: Current Assets - Inventory | D9: =G9-G10 -> 2576129000 | E9: =D9/D10 -> 15.442104 | F9: Current Assets: | G9: =G5 -> 2586439000 | J9: Current Assets - Inventory | L9: =O9-O10 -> 378802000 | M9: =L9/L10 -> 10.497492 | N9: Current Assets: | O9: =O5 -> 378802000
B10: Current Liabilities | D10: =G6 -> 166825000 | F10: Inventory: | G10: 10310000 | J10: Current Liabilities | L10: =O6 -> 36085000 | N10: Inventory: | O10: 0
A12: Gearing | I12: Gearing
B13: Long-Term Debt | D13: =G13 -> 21171000 | E13: =D13/D14 -> 0.0055206666 | F13: Long Term Debt: | G13: 21171000 | J13: Long Term Debt | L13: =O13 -> 14359000 | M13: =L13/L14 -> 0.036057867 | N13: Long-Term Debt: | O13: 14359000
B14: LT Debt + Equity | D14: =G13+G14 -> 3834863000 | F14: Total Equity: | G14: 3813692000 | J14: LT Debt + Equity | L14: =O13+O14 -> 398221000 | N14: Total Equity: | O14: 383862000
A16: Interest Cover | I16: Interest Cover
B17: Profit before Interest and Tax | D17: =G17 -> -633715000 | E17: =D17/D18 -> -7.0631736 | F17: Profit before Int & Tax: | G17: -633715000 | J17: Profit before Interest and Tax | L17: =O17 -> -232455000 | M17: =L17/L18 -> -14.153373 | N17: Profit before Interest andTax: | O17: -232455000
B18: Interest Payable | D18: =G18 -> 89721000 | F18: Interest Paid and Payable: | G18: 89721000 | J18: Interest Paid and Payable | L18: =O18 -> 16424000 | N18: Interest Payable: | O18: 16424000
A20: Dividend Cover | I20: Dividend Cover
B21: Profit After Tax | D21: =G21 -> -512121000 | E21: =D21/D22 -> #DIV/0! | F21: Profit after Tax: | G21: -512121000 | J21: Profit After Tax | L21: =O21 -> -331647000 | M21: =L21/L22 -> #DIV/0! | N21: Profit after Tax: | O21: =-331647000 -> -331647000
B22: Dividend Paid and Payable | D22: =G22 -> 0 | F22: Dividend: | G22: 0 | J22: Dividend Paid and Payable | L22: =O22 -> 0 | N22: Dividend: | O22: 0
A26: PROFITABILITY RATIOS | I26: PROFITABILITY RATIOS
A28: Gross Margin | I28: Gross Margin
B29: Gross Profit | D29: =G29 -> 52528000 | E29: =D29/D30 -> 0.40401181 | F29: Gross Profit | G29: 52528000 | J29: Gross Profit | L29: =O29 -> 22476000 | M29: =L29/L30 -> 0.52181181 | N29: Gross Profit | O29: 22476000
B30: Sales | D30: =G30 -> 130016000 | F30: Sales | G30: 130016000 | J30: Sales | L30: =O30 -> 43073000 | N30: Sales | O30: 43073000
A32: Net Margin | I32: Net Margin
B33: Net Profit Before Tax | D33: =G33 -> -633715000 | E33: =D33/D34 -> -4.8741309 | F33: Profit before Tax: | G33: =G17 -> -633715000 | J33: Net Profit Before Tax | L33: =O33 -> -232455000 | M33: =L33/L34 -> -5.3967683 | N33: Profit before Tax: | O33: =O17 -> -232455000
B34: Sales | D34: =G34 -> 130016000 | F34: Sales | G34: =G30 -> 130016000 | J34: Sales | L34: =O34 -> 43073000 | N34: Sales | O34: =O30 -> 43073000
A36: Sales-to-Assets | I36: Sales-to-Assets
B37: Sales | D37: =G37 -> 130016000 | E37: =D37/D38 -> 0.019788267 | F37: Sales | G37: =G30 -> 130016000 | J37: Sales | L37: =O37 -> 43073000 | M37: =L37/L38 -> 0.084724659 | N37: Sales | O37: =O30 -> 43073000
B38: Total Assets | D38: =G38 -> 6570358000 | F38: Total Assets | G38: 6570358000 | J38: Total Assets | L38: =O38 -> 508388000 | N38: Total Assets | O38: 508388000
A40: Return on Assets | I40: Return on Assets
B41: Net Profit Before Tax | D41: =G41 -> -633715000 | E41: =D41/D42 -> -0.096450604 | F41: Profit before Tax: | G41: =G17 -> -633715000 | J41: Net Profit Before Tax | L41: =O41 -> -232455000 | M41: =L41/L42 -> -0.45723935 | N41: Profit before Tax: | O41: =O17 -> -232455000
B42: Total Assets | D42: =G42 -> 6570358000 | F42: Total Assets | G42: =G38 -> 6570358000 | J42: Total Assets | L42: =O42 -> 508388000 | N42: Total Assets | O42: =O38 -> 508388000
A45: EFFICIENCY RATIOS | I45: EFFICIENCY RATIOS
A47: Inventory Turnover | I47: Inventory Turnover
B48: Cost of Goods Sold | D48: =G48 -> 77488000 | E48: =D48/D49 -> 7.5158099 | F48: Cost of Goods Sold: | G48: 77488000 | J48: Cost of Goods Sold | L48: =O48 -> 20597000 | M48: =L48/L49 -> #DIV/0! | N48: Cost of Goods Sold: | O48: 20597000
B49: Inventory | D49: =G49 -> 10310000 | F49: Inventory: | G49: =G10 -> 10310000 | J49: Inventory | L49: =O49 -> 0 | N49: Inventory: | O49: 0
A51: Inventory Days | I51: Inventory Days
B52: 365 | D52: 365 | E52: =D52/D53 -> 48.564294 | F52: Inventory Turnover: | G52: =E48 -> 7.5158099 | J52: 365 | L52: 365 | M52: =L52/L53 -> #DIV/0! | N52: Inventory Turnover: | O52: =M48 -> #DIV/0!
B53: Inventory Turnover | D53: =G52 -> 7.5158099 | J53: Inventory Turnover | L53: =O52 -> #DIV/0!
A55: Accounts Receivable Days | I55: Accounts Receivable Days
B56: Accounts Receivable x 365 | D56: =G56*365 -> 24284180000 | E56: =D56/D57 -> 186.7784 | F56: Accounts Receivable: | G56: 66532000 | J56: Accounts Receivable x 365 | L56: =O56*365 -> 3718620000 | M56: =L56/L57 -> 86.33297 | N56: Accounts Receivable: | O56: 10188000
...

Sheet Summary Notes
A1: RATIOS | B1: 2025 | C1: 2024 | D1: Analysis | E1: Notes/Comments
A2: LIQUIDITY AND SOLVENCY RATIOS - ability to pay its short term debts
A3: Current | B3: =Ratios!E5 -> 15.503905 | C3: =Ratios!M5 -> 10.497492 | D3: 1. Capital Raise in Oct 2025 where IONQ closed a $2 Billion equity offering. This created a spike in Cash and Cash equivalents and Short-Term Investments. By end of Q3 2025, their total liquidity position (cash + investments) reached approx $1.485 Billion (compared to $363.8 Million at end of 2024). 2. During 2025, IONQ acquired Oxford Ionics and Vector Atomic, and announced intent to acquire SkyWater. The strategy was to fund their quantum goals without taking on high-interest long-term debt thereby maintaining a high balance of short-term investments. 3. While IonQ’s Current Liabilities did grow (from $36.1 Million to $166.9 Million) as they scaled their manufacturing facilities and headcount, they did not grow at the same pace as their cash reserves (from $378.8 Million to $2.59 Billion). Overall, the ratio did not go up because they paid off debt, but it grew mostly because of raising a massive amount of cash to fund the company. | E3: Heights Capital Management, Inc. invested $2B in IONQ, in return they got common stock, pre-funded and long-term warrants. Common stock at $93, pre-funded and long-term warrants at $155, which is above base price showing that investor is confident with IONQ. The deal was struck by JP Morgan in Oct 9 2025. https://www.ionq.com/news/ionq-announces-pricing-of-usd2-0-billion-equity-offering https://www.ionq.com/news/ionq-announces-intent-to-acquire-vector-atomic-expanding-into-quantum https://www.ionq.com/news/ionq-to-acquire-skywater-technology-creating-the-only-vertically-integrated-full-stack-quantum-platform-company
A4: Quick | B4: =Ratios!E9 -> 15.442104 | C4: =Ratios!M9 -> 10.497492 | D4: 1. Capital Raise in Oct 2025 where IONQ closed a $2 Billion equity offering. This created a spike in Cash and Cash equivalents and Short-Term Investments. By end of Q3 2025, their total liquidity position (cash + investments) reached approx $1.485 Billion (compared to $363.8 Million at end of 2024). 2. During 2025, IONQ acquired Oxford Ionics and Vector Atomic, and announced intent to acquire SkyWater. The strategy was to fund their quantum goals without taking on high-interest long-term debt thereby maintaining a high balance of short-term investments. 3. While IonQ’s Current Liabilities did grow (from $36.1 Million to $166.9 Million) as they scaled their manufacturing facilities and headcount, they did not grow at the same pace as their cash reserves (from $378.8 Million to $2.59 Billion). Overall, the ratio did not go up because they paid off debt, but it grew mostly because of raising a massive amount of cash to fund the company.
A5: Gearing | B5: =Ratios!E13 -> 0.0055206666 | C5: =Ratios!M13 -> 0.036057867 | D5: Best to NOT include in the analysis or presentation part. | E5: There are no long term debt as such according to the financial statement verified by Gemini. It said, if it really wanted to include 'long-term debt" like term, then it asked me to use "Operating lease liabilities, net of current portion"
A6: Interest Cover | B6: =Ratios!E17 -> -7.0631736 | C6: =Ratios!M17 -> -14.153373 | D6: 1. The shift from -14.15 to-7.06 means gap between operating losses and interest obligations is narrowing. Thus, the company is becoming more efficient in its losses, it is most likely due to revenue scaling faster than operating expenses. 2. IONQ prioritise R&D over immediate profitability. Also R&D remain the highest contributor to negative EBIT as they are developing Tempo and Barium systems. 3. Even though operating profit can’t cover interest, the cash reserves (cash and cash equivalents) can do it thousand times over. | E6: https://finance.yahoo.com/news/ionqs-quantum-roadmap-foundry-strategy-162400233.html
A7: Dividend Cover | B7: =Ratios!E21 -> #DIV/0! | C7: =Ratios!M21 -> #DIV/0! | D7: Company does not provide dividends.
A9: PROFITABILITY RATIOS - ability of a company to generate income (profit)
A10: Gross Margin | B10: =Ratios!E29 -> 0.40401181 | C10: =Ratios!M29 -> 0.52181181 | D10: Cost of producing revenue is rising faster than the revenue itself. 1. Shift from service (QCaaS) to hardware sales (like Forte or Tempo) in 2025 2. IonQ may have invested in new production facilities in 2025 (moving from R&D or prototyping to production stage), which means depreciation and labour costs of these facilities are factored in gross margin. 3. Price of specialised chips, cryogenics, or rare-earth materials increased in 2025 OR IonQ may had to pay premiums to secure supply chain. 4. To gain market share and get their systems into the hands of national labs or big corporations, IonQ may be lowering sales price of a system while production costs remain high. They intentionally sacrifice short-term margin (dropping to 40%) to lock-in long-term customers and ecosystem dominance. | E10: https://quantumcomputingreport.com/ionq-reports-fourth-quarter-and-full-year-2025-financial-results-first-quantum-company-to-surpass-100m-annual-revenue/
A11: Net Margin | B11: =Ratios!E33 -> -4.8741309 | C11: =Ratios!M33 -> -5.3967683 | D11: The move from -540% to -487% indicates that IonQ revenue is growing faster than its losses. - The revenue tripled from $43M to $130M which shows that although company is still losing money, every new dollar of revenue is starting to cover a slightly larger portion of the fixed over head costs. - The margin remains largely negative because IonQ is no longer just R&D, it is building a global supply chain (60% of revenue comes from commercial customers rather than government grants). Also, the operating costs increased in 2025 due to SkyWater and Oxford Ionics acquisition. - Major reason being Fair Value of Warrant Liabilities, as IonQ’s stock price rose in 2025, accounting rules forced them to record a “loss” on the warrants they issued to early investors (Heights Capital Management, Inc.). This is a “paper loss” that doesn’t affect their cash bank account but makes the Net Margin look significantly worse. | E11: https://quantumcomputingreport.com/ionq-reports-fourth-quarter-and-full-year-2025-financial-results-first-quantum-company-to-surpass-100m-annual-revenue/
A12: Sales-to-Assets | B12: =Ratios!E37 -> 0.019788267 | C12: =Ratios!M37 -> 0.084724659 | D12: Sales-to-Assets ratio dipped because Total Assets surged over $6.5B following major acquisitions in 2025. Thus, assets grew much faster than Sales. - In 2025, IonQ raised capital, ending the year with $3.3B in cash and cash equivalents and short-term investments. As cash is an asset and doesn’t generate sales immediately, it caused the ratio to go from 8% to 2%. When IonQ acquired the companies listed above, they added massive amounts of Goodwill, Intangible Assets, and Property & Equipment. - In 2024, IonQ mainly focused on R&D and cloud access. Now they have become a hardware manufacturer, which means they require expensive factories and equipment to generate the same dollar of sales (Full-Stack Model). Overall, this ratio should not be seen as poor performance, but it should be looked at as a “delayed reaction”. | E12: https://quantumcomputingreport.com/ionq-reports-fourth-quarter-and-full-year-2025-financial-results-first-quantum-company-to-surpass-100m-annual-revenue/
A13: Return on Assets | B13: =Ratios!E41 -> -0.096450604 | C13: =Ratios!M41 -> -0.45723935 | D13: The most significant reason that RoA improved drastically is that Total Assets grew by over 1100% (from $508M to $6.5B) - Revenue tripled to $130M in 2025 - Acquisitions added tangible manufacturing assets to the balance sheet - Shift from R&D to industrial leader in QC | E13: https://www.businesswire.com/news/home/20260225290197/en/IonQ-Announces-Fourth-Quarter-and-Full-Year-2025-Financial-Results
A15: EFFICIENCY RATIOS - company’s ability to effectively employ its resources
A16: Inventory Turnover | B16: =Ratios!E48 -> 7.5158099 | C16: =Ratios!M48 -> #DIV/0! | D16: No Inventory
A17: Inventory Days | B17: =Ratios!E52 -> 48.564294 | C17: =Ratios!M52 -> #DIV/0! | D17: No Inventory
A18: Account Receivable Days | B18: =Ratios!E56 -> 186.7784 | C18: =Ratios!M56 -> 86.33297 | D18: Accounts Receivable Days from 86 to 187 days typically is a “red flag” for a mature company, but for IonQ in 2025 it reflects a change in customer base. In 2024, IonQ mostly dealt with government grants and cloud providers who pay quickly. In 2025, 60% of revenue came from commercial customers and international sales. Here, large corporations and government entities often have long payment cycles, and the jump suggests IonQ is shipping complex physical systems where the final payment is made only after a lengthy installation and testing period. Increase in Accounts Payable Days (from 93 to 123 days) is generally a good sign for cash flow, it means the company is keeping its cash longer before paying suppliers. Following acquisitions and growth of their $3.3B in cash war chest, IonQ now has significantly more bargaining power. By taking 123 days to pay instead of 93, they are effectively using their suppliers as a source of “interest-free” short-term financing to fund their rapid expansion. When AR days (187) is greater than AP days (123), it has a cash gap (of 64 days). It means IonQ is waiting 64 days longer to get paid by customers than it takes to pay its own bills. This can lead to “liquidity crunch” if a company doesn’t have enough cash. But this is not the case as they hold $3.3B in cash, thus they can afford to wait 187 days for a customer check.
A19: Account Payable Days | B19: =Ratios!E60 -> 123.12061 | C19: =Ratios!M60 -> 92.680973
A21: INVESTMENT RATIOS - help potential investors to decide whether to buy shares of the company or not
A22: Earnings Per Share | B22: =Ratios!G80 -> -1.82 | C22: =Ratios!O80 -> -1.56
A23: Price/Earnings Ratio | B23: =Ratios!E79 -> -24.653846 | C23: =Ratios!M79 -> -26.75641
A24: Return on Equity | B24: =Ratios!E83 -> -0.1662355 | C24: =Ratios!M83 -> -0.60585171
A25: Return on Capital Employed | B25: =Ratios!E88 -> -0.11466857 | C25: =Ratios!M88 -> -0.24409966
A28: Below links recommend buying IONQ stocks
A29: https://www.fool.com/investing/2026/03/29/prediction-these-2-quantum-computing-stocks-will-s/
A30: https://www.fool.com/investing/2026/03/29/1-unstoppable-quantum-computing-stock-to-buy-befor/
